Workbook

Sheet Datos
A1: No | B1: X real | C1: Y real | D1: X real ^2 | E1: x | F1: y | G1: xy | H1: x^2 | I1: Y Est | J1: e | K1: e^2 | L1: y^2 | M1: INTERVALO VALOR MEDIO Y | N1: Límite Inferior | O1: Límite Superior | P1: INTERVALO VALOR PUNTUAL Y | Q1: Límite Inferior 2 | R1: Límite Superior 2
A2: =ROW(B2)-1 -> 1 | B2: 269 | C2: 393 | D2: =B2*B2 -> 72361 | E2: =B2-'Cálculos'!$B$3 -> 56.4 | F2: =C2-'Cálculos'!$C$3 -> 48.15 | G2: =E2*F2 -> 2715.66 | H2: =E2*E2 -> 3180.96 | I2: ='Cálculos'!$C$19+('Cálculos'!$C$12*B2) -> 422.49494 | J2: =C2-I2 -> -29.494937 | K2: =J2*J2 -> 869.95132 | L2: =F2*F2 -> 2318.4225 | M2: ='Cálculos'!$M$15*'Cálculos'!$J$27*SQRT((1/'Cálculos'!$B$5)+(POWER(B2-'Cálculos'!$B$3,2)/'Cálculos'!$H$2)) -> 17.289485 | N2: =I2-M2 -> 405.20545 | O2: =I2+M2 -> 439.78442 | P2: ='Cálculos'!$M$15*'Cálculos'!$J$27*SQRT(1+(1/'Cálculos'!$B$5)+(POWER(B2-'Cálculos'!$B$3,2)/'Cálculos'!$H$2)) -> 54.254699 | Q2: =I2-P2 -> 368.24024 | R2: =I2+P2 -> 476.74964
A3: =ROW(B3)-1 -> 2 | B3: 225 | C3: 370 | D3: =B3*B3 -> 50625 | E3: =B3-'Cálculos'!$B$3 -> 12.4 | F3: =C3-'Cálculos'!$C$3 -> 25.15 | G3: =E3*F3 -> 311.86 | H3: =E3*E3 -> 153.76 | I3: ='Cálculos'!$C$19+('Cálculos'!$C$12*B3) -> 361.92087 | J3: =C3-I3 -> 8.0791273 | K3: =J3*J3 -> 65.272297 | L3: =F3*F3 -> 632.5225 | M3: ='Cálculos'!$M$15*'Cálculos'!$J$27*SQRT((1/'Cálculos'!$B$5)+(POWER(B3-'Cálculos'!$B$3,2)/'Cálculos'!$H$2)) -> 11.844403 | N3: =I3-M3 -> 350.07647 | O3: =I3+M3 -> 373.76528 | P3: ='Cálculos'!$M$15*'Cálculos'!$J$27*SQRT(1+(1/'Cálculos'!$B$5)+(POWER(B3-'Cálculos'!$B$3,2)/'Cálculos'!$H$2)) -> 52.772492 | Q3: =I3-P3 -> 309.14838 | R3: =I3+P3 -> 414.69336
A4: =ROW(B4)-1 -> 3 | B4: 167 | C4: 322 | D4: =B4*B4 -> 27889 | E4: =B4-'Cálculos'!$B$3 -> -45.6 | F4: =C4-'Cálculos'!$C$3 -> -22.85 | G4: =E4*F4 -> 1041.96 | H4: =E4*E4 -> 2079.36 | I4: ='Cálculos'!$C$19+('Cálculos'!$C$12*B4) -> 282.07324 | J4: =C4-I4 -> 39.926758 | K4: =J4*J4 -> 1594.146 | L4: =F4*F4 -> 522.1225 | M4: ='Cálculos'!$M$15*'Cálculos'!$J$27*SQRT((1/'Cálculos'!$B$5)+(POWER(B4-'Cálculos'!$B$3,2)/'Cálculos'!$H$2)) -> 15.530564 | N4: =I4-M4 -> 266.54268 | O4: =I4+M4 -> 297.60381 | P4: ='Cálculos'!$M$15*'Cálculos'!$J$27*SQRT(1+(1/'Cálculos'!$B$5)+(POWER(B4-'Cálculos'!$B$3,2)/'Cálculos'!$H$2)) -> 53.720056 | Q4: =I4-P4 -> 228.35319 | R4: =I4+P4 -> 335.7933
A5: =ROW(B5)-1 -> 4 | B5: 246 | C5: 402 | D5: =B5*B5 -> 60516 | E5: =B5-'Cálculos'!$B$3 -> 33.4 | F5: =C5-'Cálculos'!$C$3 -> 57.15 | G5: =E5*F5 -> 1908.81 | H5: =E5*E5 -> 1115.56 | I5: ='Cálculos'!$C$19+('Cálculos'!$C$12*B5) -> 390.83122 | J5: =C5-I5 -> 11.168778 | K5: =J5*J5 -> 124.74161 | L5: =F5*F5 -> 3266.1225 | M5: ='Cálculos'!$M$15*'Cálculos'!$J$27*SQRT((1/'Cálculos'!$B$5)+(POWER(B5-'Cálculos'!$B$3,2)/'Cálculos'!$H$2)) -> 13.809118 | N5: =I5-M5 -> 377.0221 | O5: =I5+M5 -> 404.64034 | P5: ='Cálculos'!$M$15*'Cálculos'!$J$27*SQRT(1+(1/'Cálculos'!$B$5)+(POWER(B5-'Cálculos'!$B$3,2)/'Cálculos'!$H$2)) -> 53.24789 | Q5: =I5-P5 -> 337.58333 | R5: =I5+P5 -> 444.07911
A6: =ROW(B6)-1 -> 5 | B6: 225 | C6: 369 | D6: =B6*B6 -> 50625 | E6: =B6-'Cálculos'!$B$3 -> 12.4 | F6: =C6-'Cálculos'!$C$3 -> 24.15 | G6: =E6*F6 -> 299.46 | H6: =E6*E6 -> 153.76 | I6: ='Cálculos'!$C$19+('Cálculos'!$C$12*B6) -> 361.92087 | J6: =C6-I6 -> 7.0791273 | K6: =J6*J6 -> 50.114043 | L6: =F6*F6 -> 583.2225 | M6: ='Cálculos'!$M$15*'Cálculos'!$J$27*SQRT((1/'Cálculos'!$B$5)+(POWER(B6-'Cálculos'!$B$3,2)/'Cálculos'!$H$2)) -> 11.844403 | N6: =I6-M6 -> 350.07647 | O6: =I6+M6 -> 373.76528 | P6: ='Cálculos'!$M$15*'Cálculos'!$J$27*SQRT(1+(1/'Cálculos'!$B$5)+(POWER(B6-'Cálculos'!$B$3,2)/'Cálculos'!$H$2)) -> 52.772492 | Q6: =I6-P6 -> 309.14838 | R6: =I6+P6 -> 414.69336
A7: =ROW(B7)-1 -> 6 | B7: 264 | C7: 421 | D7: =B7*B7 -> 69696 | E7: =B7-'Cálculos'!$B$3 -> 51.4 | F7: =C7-'Cálculos'!$C$3 -> 76.15 | G7: =E7*F7 -> 3914.11 | H7: =E7*E7 -> 2641.96 | I7: ='Cálculos'!$C$19+('Cálculos'!$C$12*B7) -> 415.61152 | J7: =C7-I7 -> 5.3884792 | K7: =J7*J7 -> 29.035708 | L7: =F7*F7 -> 5798.8225 | M7: ='Cálculos'!$M$15*'Cálculos'!$J$27*SQRT((1/'Cálculos'!$B$5)+(POWER(B7-'Cálculos'!$B$3,2)/'Cálculos'!$H$2)) -> 16.452378 | N7: =I7-M7 -> 399.15914 | O7: =I7+M7 -> 432.0639 | P7: ='Cálculos'!$M$15*'Cálculos'!$J$27*SQRT(1+(1/'Cálculos'!$B$5)+(POWER(B7-'Cálculos'!$B$3,2)/'Cálculos'!$H$2)) -> 53.993766 | Q7: =I7-P7 -> 361.61776 | R7: =I7+P7 -> 469.60529
A8: =ROW(B8)-1 -> 7 | B8: 188 | C8: 289 | D8: =B8*B8 -> 35344 | E8: =B8-'Cálculos'!$B$3 -> -24.6 | F8: =C8-'Cálculos'!$C$3 -> -55.85 | G8: =E8*F8 -> 1373.91 | H8: =E8*E8 -> 605.16 | I8: ='Cálculos'!$C$19+('Cálculos'!$C$12*B8) -> 310.98359 | J8: =C8-I8 -> -21.983591 | K8: =J8*J8 -> 483.27828 | L8: =F8*F8 -> 3119.2225 | M8: ='Cálculos'!$M$15*'Cálculos'!$J$27*SQRT((1/'Cálculos'!$B$5)+(POWER(B8-'Cálculos'!$B$3,2)/'Cálculos'!$H$2)) -> 12.804097 | N8: =I8-M8 -> 298.17949 | O8: =I8+M8 -> 323.78769 | P8: ='Cálculos'!$M$15*'Cálculos'!$J$27*SQRT(1+(1/'Cálculos'!$B$5)+(POWER(B8-'Cálculos'!$B$3,2)/'Cálculos'!$H$2)) -> 52.996141 | Q8: =I8-P8 -> 257.98745 | R8: =I8+P8 -> 363.97973
A9: =ROW(B9)-1 -> 8 | B9: 245 | C9: 363 | D9: =B9*B9 -> 60025 | E9: =B9-'Cálculos'!$B$3 -> 32.4 | F9: =C9-'Cálculos'!$C$3 -> 18.15 | G9: =E9*F9 -> 588.06 | H9: =E9*E9 -> 1049.76 | I9: ='Cálculos'!$C$19+('Cálculos'!$C$12*B9) -> 389.45454 | J9: =C9-I9 -> -26.454538 | K9: =J9*J9 -> 699.8426 | L9: =F9*F9 -> 329.4225 | M9: ='Cálculos'!$M$15*'Cálculos'!$J$27*SQRT((1/'Cálculos'!$B$5)+(POWER(B9-'Cálculos'!$B$3,2)/'Cálculos'!$H$2)) -> 13.683698 | N9: =I9-M9 -> 375.77084 | O9: =I9+M9 -> 403.13824 | P9: ='Cálculos'!$M$15*'Cálculos'!$J$27*SQRT(1+(1/'Cálculos'!$B$5)+(POWER(B9-'Cálculos'!$B$3,2)/'Cálculos'!$H$2)) -> 53.215501 | Q9: =I9-P9 -> 336.23904 | R9: =I9+P9 -> 442.67004
A10: =ROW(B10)-1 -> 9 | B10: 144 | C10: 229 | D10: =B10*B10 -> 20736 | E10: =B10-'Cálculos'!$B$3 -> -68.6 | F10: =C10-'Cálculos'!$C$3 -> -115.85 | G10: =E10*F10 -> 7947.31 | H10: =E10*E10 -> 4705.96 | I10: ='Cálculos'!$C$19+('Cálculos'!$C$12*B10) -> 250.40953 | J10: =C10-I10 -> -21.409527 | K10: =J10*J10 -> 458.36783 | L10: =F10*F10 -> 13421.222 | M10: ='Cálculos'!$M$15*'Cálculos'!$J$27*SQRT((1/'Cálculos'!$B$5)+(POWER(B10-'Cálculos'!$B$3,2)/'Cálculos'!$H$2)) -> 19.463862 | N10: =I10-M10 -> 230.94566 | O10: =I10+M10 -> 269.87339 | P10: ='Cálculos'!$M$15*'Cálculos'!$J$27*SQRT(1+(1/'Cálculos'!$B$5)+(POWER(B10-'Cálculos'!$B$3,2)/'Cálculos'!$H$2)) -> 54.986252 | Q10: =I10-P10 -> 195.42327 | R10: =I10+P10 -> 305.39578
A11: =ROW(B11)-1 -> 10 | B11: 189 | C11: 311 | D11: =B11*B11 -> 35721 | E11: =B11-'Cálculos'!$B$3 -> -23.6 | F11: =C11-'Cálculos'!$C$3 -> -33.85 | G11: =E11*F11 -> 798.86 | H11: =E11*E11 -> 556.96 | I11: ='Cálculos'!$C$19+('Cálculos'!$C$12*B11) -> 312.36027 | J11: =C11-I11 -> -1.3602745 | K11: =J11*J11 -> 1.8503467 | L11: =F11*F11 -> 1145.8225 | M11: ='Cálculos'!$M$15*'Cálculos'!$J$27*SQRT((1/'Cálculos'!$B$5)+(POWER(B11-'Cálculos'!$B$3,2)/'Cálculos'!$H$2)) -> 12.70508 | N11: =I11-M11 -> 299.65519 | O11: =I11+M11 -> 325.06535 | P11: ='Cálculos'!$M$15*'Cálculos'!$J$27*SQRT(1+(1/'Cálculos'!$B$5)+(POWER(B11-'Cálculos'!$B$3,2)/'Cálculos'!$H$2)) -> 52.972305 | Q11: =I11-P11 -> 259.38797 | R11: =I11+P11 -> 365.33258
A12: =ROW(B12)-1 -> 11 | B12: 107 | C12: 241 | D12: =B12*B12 -> 11449 | E12: =B12-'Cálculos'!$B$3 -> -105.6 | F12: =C12-'Cálculos'!$C$3 -> -103.85 | G12: =E12*F12 -> 10966.56 | H12: =E12*E12 -> 11151.36 | I12: ='Cálculos'!$C$19+('Cálculos'!$C$12*B12) -> 199.47225 | J12: =C12-I12 -> 41.527755 | K12: =J12*J12 -> 1724.5544 | L12: =F12*F12 -> 10784.823 | M12: ='Cálculos'!$M$15*'Cálculos'!$J$27*SQRT((1/'Cálculos'!$B$5)+(POWER(B12-'Cálculos'!$B$3,2)/'Cálculos'!$H$2)) -> 26.769471 | N12: =I12-M12 -> 172.70277 | O12: =I12+M12 -> 226.24172 | P12: ='Cálculos'!$M$15*'Cálculos'!$J$27*SQRT(1+(1/'Cálculos'!$B$5)+(POWER(B12-'Cálculos'!$B$3,2)/'Cálculos'!$H$2)) -> 57.976293 | Q12: =I12-P12 -> 141.49595 | R12: =I12+P12 -> 257.44854
A13: =ROW(B13)-1 -> 12 | B13: 254 | C13: 380 | D13: =B13*B13 -> 64516 | E13: =B13-'Cálculos'!$B$3 -> 41.4 | F13: =C13-'Cálculos'!$C$3 -> 35.15 | G13: =E13*F13 -> 1455.21 | H13: =E13*E13 -> 1713.96 | I13: ='Cálculos'!$C$19+('Cálculos'!$C$12*B13) -> 401.84469 | J13: =C13-I13 -> -21.844688 | K13: =J13*J13 -> 477.19039 | L13: =F13*F13 -> 1235.5225 | M13: ='Cálculos'!$M$15*'Cálculos'!$J$27*SQRT((1/'Cálculos'!$B$5)+(POWER(B13-'Cálculos'!$B$3,2)/'Cálculos'!$H$2)) -> 14.901346 | N13: =I13-M13 -> 386.94334 | O13: =I13+M13 -> 416.74603 | P13: ='Cálculos'!$M$15*'Cálculos'!$J$27*SQRT(1+(1/'Cálculos'!$B$5)+(POWER(B13-'Cálculos'!$B$3,2)/'Cálculos'!$H$2)) -> 53.541536 | Q13: =I13-P13 -> 348.30315 | R13: =I13+P13 -> 455.38622
... A21: =ROW(B21)-1 -> 20 | B21: 243 | C21: 371 | D21: =B21*B21 -> 59049 | E21: =B21-'Cálculos'!$B$3 -> 30.4 | F21: =C21-'Cálculos'!$C$3 -> 26.15 | G21: =E21*F21 -> 794.96 | H21: =E21*E21 -> 924.16 | I21: ='Cálculos'!$C$19+('Cálculos'!$C$12*B21) -> 386.70117 | J21: =C21-I21 -> -15.701172 | K21: =J21*J21 -> 246.5268 | L21: =F21*F21 -> 683.8225 | M21: ='Cálculos'!$M$15*'Cálculos'!$J$27*SQRT((1/'Cálculos'!$B$5)+(POWER(B21-'Cálculos'!$B$3,2)/'Cálculos'!$H$2)) -> 13.441045 | N21: =I21-M21 -> 373.26013 | O21: =I21+M21 -> 400.14222 | P21: ='Cálculos'!$M$15*'Cálculos'!$J$27*SQRT(1+(1/'Cálculos'!$B$5)+(POWER(B21-'Cálculos'!$B$3,2)/'Cálculos'!$H$2)) -> 53.153624 | Q21: =I21-P21 -> 333.54755 | R21: =I21+P21 -> 439.8548

Sheet Cálculos
A1: No | B1: X real | C1: Y real | D1: X real ^2 | E1: x | F1: y | G1: xy | H1: x^2 | I1: Y Est | J1: e | K1: e^2 | L1: y^2 | M1: INTERVALO VALOR MEDIO Y | N1: Límite Inferior | O1: Límite Superior | P1: INTERVALO VALOR PUNTUAL Y | Q1: Límite Inferior 2 | R1: Límite Superior 2
A2: Suma | B2: =SUM(Datos!B:B) -> 4252 | C2: =SUM(Datos!C:C) -> 6897 | D2: =SUM(Datos!D:D) -> 954442 | E2: =SUM(Datos!E:E) -> 0 | F2: =SUM(Datos!F:F) -> 0 | G2: =SUM(Datos!G:G) -> 69476.8 | H2: =SUM(Datos!H:H) -> 50466.8 | I2: =SUM(Datos!I:I) -> 6897 | J2: =SUM(Datos!J:J) -> 0 | K2: =SUM(Datos!K:K) -> 10785.001 | L2: =SUM(Datos!L:L) -> 106432.55 | M2: =SUM(Datos!M:M) -> 313.7664 | N2: =SUM(Datos!N:N) -> 6583.2336 | O2: =SUM(Datos!O:O) -> 7210.7664 | P2: =SUM(Datos!P:P) -> 1078.3387 | Q2: =SUM(Datos!Q:Q) -> 5818.6613 | R2: =SUM(Datos!R:R) -> 7975.3387
A3: Promedio | B3: =AVERAGE(Datos!B:B) -> 212.6 | C3: =AVERAGE(Datos!C:C) -> 344.85 | D3: =AVERAGE(Datos!D:D) -> 47722.1 | E3: =AVERAGE(Datos!E:E) -> 0 | F3: =AVERAGE(Datos!F:F) -> 0 | G3: =AVERAGE(Datos!G:G) -> 3473.84 | H3: =AVERAGE(Datos!H:H) -> 2523.34 | I3: =AVERAGE(Datos!I:I) -> 344.85 | J3: =AVERAGE(Datos!J:J) -> 0 | K3: =AVERAGE(Datos!K:K) -> 539.25004 | L3: =AVERAGE(Datos!L:L) -> 5321.6275 | M3: =AVERAGE(Datos!M:M) -> 15.68832 | N3: =AVERAGE(Datos!N:N) -> 329.16168 | O3: =AVERAGE(Datos!O:O) -> 360.53832 | P3: =AVERAGE(Datos!P:P) -> 53.916933 | Q3: =AVERAGE(Datos!Q:Q) -> 290.93307 | R3: =AVERAGE(Datos!R:R) -> 398.76693
A5: n | B5: =COUNT(Datos!A:A) -> 20 | E5: Realizado por: Ricardo Ortiz M.
A6: n-2 | B6: =B5-2 -> 18
E8: VARIANZAS | I8: ERROR ESTÁNDAR | L8: INTERVALOS
M10: Beta | P10: Ho: β=0 vs Ha β≠0
L11: Límite Superior | M11: =C12+(J12*M15) -> 1.6056018
C12: =G2/H2 -> 1.3766833 | G12: =C26/H2 -> 0.011872493 | I12: EE Beta | J12: =SQRT(G12) -> 0.10896097 | P12: T calculada = | Q12: =(C12-0)/J12 -> 12.634646
L13: Límite Inferior | M13: =C12-(J12*M15) -> 1.1477648
L14: % de confianza | M14: 0.95 | P14: P value = | Q14: =_xlfn.T.DIST.2T(Q12, B6) -> 2.1916358e-10
L15: t 95%, n-2 gl | M15: =TINV((1-M14),B6) -> 2.100922
M17: Alfa | P17: Ho: α=0 vs Ha α≠0
L18: Límite Superior | M18: =C19+(J19*M15) -> 102.17527
C19: =C3-(C12*B3) -> 52.167134 | G19: =(C26*D2)/(B5*H2) -> 566.58028 | I19: EE Alfa | J19: =SQRT(G19) -> 23.802947 | P19: T calculada = | Q19: =(C19-0)/J19 -> 2.191625
L20: Límite Inferior | M20: =C19-(J19*M15) -> 2.158998
P21: P value = | Q21: =_xlfn.T.DIST.2T(Q19, B6) -> 0.041799943
E24: Signo | F24: Decimales
E25: =IF(C12>=0, " + ", " - ") -> + | F25: 4 | M25: VARIANZA DEL ERROR | N25: Desv. Est.
C26: =K2/B6 -> 599.16671 | L26: Límite Inferior | M26: =C30/M29 -> 342.0945 | N26: =SQRT(M26) -> 18.495797
E27: Ec de la Recta | F27: ="Yi = " & ROUND(C19,F25) &E25 & (ABS(ROUND(C12,F25))) & " Xi" -> Yi = 52.1671 + 1.3767 Xi | I27: EE Error | J27: =SQRT(C26) -> 24.477882
L28: Límite Superior | M28: =C30/M30 -> 1310.3309 | N28: =SQRT(M28) -> 36.198493
L29: Ji cuad n-2 0.025 | M29: =_xlfn.CHISQ.INV(0.975,B6) -> 31.526378
C30: =B6*C26 -> 10785.001 | L30: Ji cuad n-2 0.975 | M30: =_xlfn.CHISQ.INV(0.025,B6) -> 8.2307462
A33: % de aceptación | B33: 0.05
A34: TABLA RESUMEN DE COEFICIENTES DEL MODELO
A36: Coeficiente | B36: Valor | C36: Error Est. | D36: T calculada | E36: Probabilidad Asociada | F36: Lim. Inf | G36: Lim Sup
A37: ALFA | B37: =C19 -> 52.167134 | C37: =J19 -> 23.802947 | D37: =Q19 -> 2.191625 | E37: =Q21 -> 0.041799943 | F37: =M20 -> 2.158998 | G37: =M18 -> 102.17527 | H37: =IF(E37>=B33, "No rechazo Ho", "Rechazo Ho") -> Rechazo Ho | I37: Alfa = 0
A38: BETA | B38: =C12 -> 1.3766833 | C38: =J12 -> 0.10896097 | D38: =Q12 -> 12.634646 | E38: =Q14 -> 2.1916358e-10 | F38: =M13 -> 1.1477648 | G38: =M11 -> 1.6056018 | H38: =IF(E38>=B33, "No rechazo Ho", "Rechazo Ho") -> Rechazo Ho | I38: Beta = 0
A41: TABLA ANOVA EN REGRESIÓN
A43: Fuente de Variación | B43: Sumas de Cuadrados | C43: Grados de Libertad | D43: Cuadrados Medios | E43: Estadística F | F43: Probabilidad Asociada
A44: Regresión | B44: =B46-B45 -> 95647.549 | C44: 1 | D44: =B44 -> 95647.549 | E44: =D44/D45 -> 159.63429 | F44: =_xlfn.F.DIST.RT(E44,1,C45) -> 2.1916358e-10
A45: No Explicada | B45: =K2 -> 10785.001 | C45: =B5-2 -> 18 | D45: =B45/C45 -> 599.16671
A46: Total | B46: =L2 -> 106432.55 | C46: =B5-1 -> 19
A49: COEFICIENTE DE DETERMINACIÓN
A52: COEF. DETERMINACIÓN | C52: =1-(K2/L2) -> 0.89866821
A56: COEF. CORRELACIÓN | C56: =SQRT(C52) -> 0.94798112
A60: GRÁFICAS
C82: Intervalo de Confianza Valor Medio | F82: Intervalo de Confianza Valor Puntual
A83: Xo | B83: Y est | C83: A | D83: Lim. Inf | E83: LimSup. | F83: B | G83: LimInf | H83: Lim. Sup
...
